<mujoco model="double_pendulum">
  <compiler angle="radian" />
  
  <option integrator="implicitfast" timestep="0.002"/>
  
  <asset>
    <material name="black" rgba="0.0 0.0 0.0 1.0" />
    <material name="blue" rgba="0.0 0.0 1.0 1.0" />
    <material name="red" rgba="1.0 0.0 0.0 1.0" />
  </asset>

  <worldbody>
    <body name="base_link" pos="0 0 0">
      <body name="link1" pos="0 0.5 1.5" euler="-1.5708 0 0">
        <inertial pos="0 0 0" euler="0 0 0" mass="1.0" diaginertia="0.03 0.04 0.05"/>
        <geom type="box" size="0.05 0.05 0.5" material="blue"/>
        <joint name="joint1" type="hinge" pos="0 0 -0.5" axis="1 0 0"/>

        <body name="link2" pos="0.1 0 1.0">
          <inertial pos="0 0 0" euler="0 0 0" mass="1.0" diaginertia="0.07 0.06 0.08"/>
          <geom type="box" size="0.05 0.05 0.5" material="red"/>
          <joint name="joint2" type="hinge" pos="0 0 -0.5" axis="1 0 0"/>
          <site name ="ee_site" type="sphere" pos="0 0 0.5" size="0.1" rgba="0 0.9 0 0.5" />
        </body>
      </body>
    </body>
  </worldbody>

  <actuator>
    <motor joint="joint1" name="motor1" gear="1"/>
    <motor joint="joint2" name="motor2" gear="1"/>
  </actuator>

  <keyframe>
    <key name="home" qpos="-0.7854 1.5708" ctrl="0 0"/>
  </keyframe>
</mujoco>
